Workbook

Sheet Tee 11h00
B2: FLIGHT GIẢI GOLF CHÀO MỪNG ĐẠI HỘI MƯỜNG THANH 2026
A4: STT | B4: Flight | C4: Holes | E4: Goler name | F4: VGA | G4: Chức vụ | H4: Low handicap index (01/1/2026 - 03/10/2026) | I4: Course HNC | J4: Division | K4: Nickname trên Vhandicap | L4: GHI CHÚ
A6: =IF(E6="","",COUNTA($E$6:E6)) -> 1 | B6: 1 | C6: 1A | D6: Ông | E6: Lê Thanh Thản | G6: =IFERROR(VLOOKUP(E6, 'DS- Title'!$A:$B, 2, 0), "") -> Chủ tịch Tập đoàn Mường Thanh
A7: =IF(E7="","",COUNTA($E$6:E7)) -> 2 | D7: Ông | E7: Trần Thanh Tú | F7: 36203 | G7: =IFERROR(VLOOKUP(E7, 'DS- Title'!$A:$B, 2, 0), "") -> Giám đốc | H7: 21 | I7: 25 | K7: Trần Thanh Tú
A8: =IF(E8="","",COUNTA($E$6:E8)) -> 3 | D8: Ông | E8: Lê Văn Cường | F8: 16461 | G8: =IFERROR(VLOOKUP(E8, 'DS- Title'!$A:$B, 2, 0), "") -> Giám đốc | H8: 14.3 | I8: 17 | K8: Lê Văn Cường
A9: =IF(E9="","",COUNTA($E$6:E9)) -> 4 | D9: Ông | E9: Trần Đình Phùng | F9: 65974 | G9: =IFERROR(VLOOKUP(E9, 'DS- Title'!$A:$B, 2, 0), "") -> Giám đốc | H9: 23.7 | I9: 29 | K9: Trần Đình Phùng
A10: =IF(E10="","",COUNTA($E$6:E10)) -> 5 | D10: Ông | E10: Hồ Trọng Hùng | F10: 37999 | G10: =IFERROR(VLOOKUP(E10, 'DS- Title'!$A:$B, 2, 0), "") -> 0 | H10: 13.8 | I10: 17 | K10: Ho Trong Hung
A11: =IF(E11="","",COUNTA($E$6:E11)) | G11: =IFERROR(VLOOKUP(E11, 'DS- Title'!$A:$B, 2, 0), "")
A12: =IF(E12="","",COUNTA($E$6:E12)) -> 6 | B12: 2 | C12: 1B | D12: Ông | E12: Lê Thanh Song | F12: 35001 | G12: =IFERROR(VLOOKUP(E12, 'DS- Title'!$A:$B, 2, 0), "") -> 0 | H12: 18.7 | I12: 23 | K12: Le Thanh Song | L12: Chú Song
A13: =IF(E13="","",COUNTA($E$6:E13)) -> 7 | D13: Ông | E13: Nguyễn Văn Thắng | F13: 90427 | G13: =IFERROR(VLOOKUP(E13, 'DS- Title'!$A:$B, 2, 0), "") -> 0 | H13: 12.1 | I13: 15 | K13: Nguyễn Văn Thắng | L13: Chú Song
A14: =IF(E14="","",COUNTA($E$6:E14)) -> 8 | D14: Ông | E14: Vũ Duy Kiên | F14: 32965 | G14: =IFERROR(VLOOKUP(E14, 'DS- Title'!$A:$B, 2, 0), "") -> 0 | H14: 17.6 | I14: 21 | K14: Vũ Duy Kiên | L14: Chú Song
A15: =IF(E15="","",COUNTA($E$6:E15)) -> 9 | D15: Ông | E15: Trần Nam Trung | F15: 50280 | G15: =IFERROR(VLOOKUP(E15, 'DS- Title'!$A:$B, 2, 0), "") -> 0 | H15: 23.8 | I15: 29 | K15: Trần Nam Trung | L15: Chú Song
A16: =IF(E16="","",COUNTA($E$6:E16)) -> 10 | D16: Ông | E16: Phạm Thanh Hải | F16: 48393 | G16: =IFERROR(VLOOKUP(E16, 'DS- Title'!$A:$B, 2, 0), "") -> 0 | H16: 21.8 | I16: 26 | K16: Phan Thanh Hai | L16: Chú Song
A17: =IF(E17="","",COUNTA($E$6:E17)) | G17: =IFERROR(VLOOKUP(E17, 'DS- Title'!$A:$B, 2, 0), "")
A18: =IF(E18="","",COUNTA($E$6:E18)) -> 11 | B18: 3 | C18: 9B | D18: Ông | E18: Phạm Lịch Sự | F18: 666999 | G18: =IFERROR(VLOOKUP(E18, 'DS- Title'!$A:$B, 2, 0), "") -> 0
A19: =IF(E19="","",COUNTA($E$6:E19)) -> 12 | D19: Ông | E19: Trần Quang Khánh | F19: 53612 | G19: =IFERROR(VLOOKUP(E19, 'DS- Title'!$A:$B, 2, 0), "") -> 0 | H19: 9.7 | I19: 12 | K19: Khánh Trần | L19: Chú Song
A20: =IF(E20="","",COUNTA($E$6:E20)) -> 13 | D20: Ông | E20: Tạ Vũ Toàn | F20: 54489 | G20: =IFERROR(VLOOKUP(E20, 'DS- Title'!$A:$B, 2, 0), "") -> 0 | H20: 13 | I20: 16 | K20: Toàn OVER | L20: Chú Song
A21: =IF(E21="","",COUNTA($E$6:E21)) -> 14 | D21: Ông | E21: Nguyễn Đình Đề | F21: 139563 | G21: =IFERROR(VLOOKUP(E21, 'DS- Title'!$A:$B, 2, 0), "") -> 0 | H21: 10.8 | I21: 13 | K21: Dechampau | L21: Chú Song
A22: =IF(E22="","",COUNTA($E$6:E22)) -> 15 | D22: Ông | E22: Nguyễn Thành Trung | F22: 121222 | G22: =IFERROR(VLOOKUP(E22, 'DS- Title'!$A:$B, 2, 0), "") -> 0 | H22: 10.7 | I22: 13 | K22: Nguyễn Thành Trung | L22: Chú Song
A23: =IF(E23="","",COUNTA($E$6:E23)) | G23: =IFERROR(VLOOKUP(E23, 'DS- Title'!$A:$B, 2, 0), "")
A24: =IF(E24="","",COUNTA($E$6:E24)) -> 16 | B24: 4 | C24: 9A | D24: Ông | E24: Nguyễn Đức Tuấn | F24: 7835 | G24: =IFERROR(VLOOKUP(E24, 'DS- Title'!$A:$B, 2, 0), "") -> 0 | H24: 8.3 | I24: 10 | K24: NĐ T 7835 | L24: Chú Song
A25: =IF(E25="","",COUNTA($E$6:E25)) -> 17 | D25: Ông | E25: Phạm Ngọc Quý | F25: 10218 | G25: =IFERROR(VLOOKUP(E25, 'DS- Title'!$A:$B, 2, 0), "") -> 0 | H25: 15.3 | I25: 19 | K25: Phạm Ngọc Qúy | L25: Chú Song
A26: =IF(E26="","",COUNTA($E$6:E26)) -> 18 | D26: Ông | E26: Nguyễn Ngọc Văn | F26: 54185 | G26: =IFERROR(VLOOKUP(E26, 'DS- Title'!$A:$B, 2, 0), "") -> 0 | H26: 6.2 | I26: 8 | K26: Văn - Adam | L26: Chú Song
A27: =IF(E27="","",COUNTA($E$6:E27)) -> 19 | D27: Ông | E27: Phan Mạnh Hà | F27: 182468 | G27: =IFERROR(VLOOKUP(E27, 'DS- Title'!$A:$B, 2, 0), "") -> 0 | H27: 10.9 | I27: 13 | K27: MrBean | L27: Chú Song
A28: =IF(E28="","",COUNTA($E$6:E28)) | G28: =IFERROR(VLOOKUP(E28, 'DS- Title'!$A:$B, 2, 0), "")
A29: =IF(E29="","",COUNTA($E$6:E29)) -> 20 | B29: 5 | C29: 8B | D29: Ông | E29: Lê Thanh Mai | G29: =IFERROR(VLOOKUP(E29, 'DS- Title'!$A:$B, 2, 0), "") -> 0 | L29: Chú Song
A30: =IF(E30="","",COUNTA($E$6:E30)) -> 21 | D30: Ông | E30: Trần Trung Anh | F30: 586888 | G30: =IFERROR(VLOOKUP(E30, 'DS- Title'!$A:$B, 2, 0), "") -> 0 | H30: 17.1 | I30: 21 | K30: Trần Trung Anh | L30: Chú Song
A31: =IF(E31="","",COUNTA($E$6:E31)) -> 22 | D31: Ông | E31: Trần Minh Tuấn | F31: 49072 | G31: =IFERROR(VLOOKUP(E31, 'DS- Title'!$A:$B, 2, 0), "") -> 0 | H31: 17.9 | I31: 22 | K31: Mr Tuấn | L31: Chú Song
A32: =IF(E32="","",COUNTA($E$6:E32)) -> 23 | D32: Ông | E32: Nguyễn Văn Đức | F32: 13856 | G32: =IFERROR(VLOOKUP(E32, 'DS- Title'!$A:$B, 2, 0), "") -> 0 | H32: 22.4 | I32: 27 | K32: Nguyễn Văn Đức | L32: Chú Song
A33: =IF(E33="","",COUNTA($E$6:E33)) | G33: =IFERROR(VLOOKUP(E33, 'DS- Title'!$A:$B, 2, 0), "")
A34: =IF(E34="","",COUNTA($E$6:E34)) -> 24 | B34: 6 | C34: 8A | D34: Ông | E34: Vũ Văn Hiểu | F34: 54853 | G34: =IFERROR(VLOOKUP(E34, 'DS- Title'!$A:$B, 2, 0), "") -> 0 | H34: 13.7 | I34: 17 | K34: Vũ Xuân Hiểu | L34: Chú Song
A35: =IF(E35="","",COUNTA($E$6:E35)) -> 25 | D35: Ông | E35: Uông Ngọc Ân | F35: 43103 | G35: =IFERROR(VLOOKUP(E35, 'DS- Title'!$A:$B, 2, 0), "") -> 0 | H35: 17.6 | I35: 21 | K35: Uông Ngọc Ân | L35: Chú Song
A36: =IF(E36="","",COUNTA($E$6:E36)) -> 26 | D36: Ông | E36: Lê Đình Phương | F36: 71955 | G36: =IFERROR(VLOOKUP(E36, 'DS- Title'!$A:$B, 2, 0), "") -> 0 | H36: 16.1 | I36: 20 | K36: LÊ Đình Phương | L36: Chú Song
A37: =IF(E37="","",COUNTA($E$6:E37)) -> 27 | D37: Ông | E37: Dương Hồng Khang | F37: 82234 | G37: =IFERROR(VLOOKUP(E37, 'DS- Title'!$A:$B, 2, 0), "") -> 0 | H37: 17 | I37: 21 | K37: Dương Khang | L37: Chú Song
A38: =IF(E38="","",COUNTA($E$6:E38)) | G38: =IFERROR(VLOOKUP(E38, 'DS- Title'!$A:$B, 2, 0), "")
A39: =IF(E39="","",COUNTA($E$6:E39)) -> 28 | B39: 7 | C39: 7A | D39: Ông | E39: Bùi Xuân Cường | F39: 916007 | G39: =IFERROR(VLOOKUP(E39, 'DS- Title'!$A:$B, 2, 0), "") -> 0 | H39: 14.3 | I39: 17 | K39: Bùi Xuân Cường | L39: A Kiên
A40: =IF(E40="","",COUNTA($E$6:E40)) -> 29 | D40: Ông | E40: Đỗ Trung Kiên | F40: 180483 | G40: =IFERROR(VLOOKUP(E40, 'DS- Title'!$A:$B, 2, 0), "") -> Tổng Giám Đốc Cienco5 | H40: 11.4 | I40: 14 | K40: Tập Đánh Golf | L40: A Kiên
A41: =IF(E41="","",COUNTA($E$6:E41)) -> 30 | D41: Ông | E41: Trần Thanh Tùng | F41: 96074 | G41: =IFERROR(VLOOKUP(E41, 'DS- Title'!$A:$B, 2, 0), "") -> Giám đốc | H41: 10 | I41: 12 | K41: Trần Thanh Tùng | L41: NBI
A42: =IF(E42="","",COUNTA($E$6:E42)) -> 31 | D42: Ông | E42: Huỳnh Thiên | F42: 20601 | G42: =IFERROR(VLOOKUP(E42, 'DS- Title'!$A:$B, 2, 0), "") -> 0 | H42: 9.3 | I42: 11 | K42: Huynh Thien | L42: NBI
A43: =IF(E43="","",COUNTA($E$6:E43)) -> 32 | D43: Ông | E43: Đoàn Khắc Thiện | G43: =IFERROR(VLOOKUP(E43, 'DS- Title'!$A:$B, 2, 0), "") -> 0 | L43: NBI
...

Sheet Tee 5h30
B1: GIẢI GOLF CHÀO MỪNG ĐẠI HỘI MƯỜNG THANH 2026
B2: Shortgun : 6h00 ngày 25/10/2026 - Sân golf Tràng An, Ninh Bình
B3: Flight | C3: Holes | D3: Goler name | E3: VGA | F3: Low handicap index (01/1/2026 - 03/10/2026) | G3: Course HNC | H3: Division | I3: Nickname trên Vhandicap
B5: 1 | C5: 1 | D5: Lê Thị Hoàng Yến | E5: 90036 | F5: 21.6 | G5: 24 | I5: Bum Bum
D6: Nguyễn Văn Hải | E6: 71649 | F6: 12.4 | G6: 15 | I6: Nguyễn Văn Hải
D7: Nguyễn Văn Phúc | E7: 45300 | F7: 16.4 | G7: 20 | I7: Nguyễn Phúc
B9: 2 | C9: 10 | D9: Trần Khắc Tường Duy | E9: 106305 | F9: 17.9 | G9: 22 | I9: Duy golf
D10: Nguyễn Huy Hoàng | E10: 158134 | F10: 14.4 | G10: 17 | I10: Hoàng Dzai
D11: Bùi Văn Tâm | E11: 138068 | F11: 16.5 | G11: 20 | I11: Tâm Xiều
D12: Phan Trọng Hợp | E12: 34895 | F12: 16.7 | G12: 20 | I12: Phan Trọng Hợp
B14: 3 | C14: 11 | D14: Hồ Minh Tuấn | E14: 130045 | F14: 29.9 | G14: 36 | I14: Hồ Minh Tuấn
D15: Phùng Thị Thơm | E15: 176170 | F15: 36 | G15: 44 | I15: Hương Thơm
D16: Trần Tuấn Anh | E16: 67832 | F16: 17.3 | G16: 21 | I16: Trần Tuấn Anh
D17: Lương Tú Thưởng | E17: 69508 | F17: 13.3 | G17: 16 | I17: Cậu Ấm
B19: 4 | C19: 12 | D19: Nguyễn Công Hùng | E19: 58675 | F19: 9.6 | G19: 12 | I19: Nguyễn Công Hùng
D20: Hoàng Văn Lực | E20: 123208 | F20: 13.5 | G20: 16 | I20: Hoàng Văn Lực
D21: Trần Quốc Trung | E21: 15690 | F21: 16.8 | G21: 20 | I21: Trần Quốc Trung
D22: Phan Văn Toàn | E22: 62583 | F22: 11.5 | G22: 14 | I22: Phan Văn Toàn
B24: 5 | C24: 13 | D24: Lê Thị Lưu | E24: 100359 | F24: 21 | G24: 25 | I24: Lê Lưu
D25: Nguyễn Thị Quỳnh | E25: 412744 | F25: 24.3 | I25: Nguyễn Thị Quỳnh
D26: Trần Thị Toàn | E26: 94501 | F26: 20.6 | I26: Thủy Toàn
B28: 6 | C28: 1 | D28: Đậu Ngọc Long | E28: 52479 | F28: 20.3 | G28: 25 | I28: Đức Sang | K28: =148+28 -> 176
D29: Tăng Văn Luyện | E29: 57224 | F29: 18 | G29: 22 | I29: Đức Thịnh
D30: Võ Trường Giang
D31: Lê Hữu Xuân | E31: 165642 | F31: 21 | G31: 25 | I31: Tít Mít
B33: 7 | C33: 2 | D33: Đào Ngọc Tâm
D34: Đậu Xuân Khánh | E34: 611188 | F34: 14.6 | G34: 18 | I34: Đậu Xuân Khánh
D35: Lê Quang Huy | E35: 108018 | F35: 20.9 | G35: 25 | I35: Lê Quang Huy
D36: Thái Thanh Phong | E36: 19045 | F36: 13.9 | G36: 17 | I36: Thảo Trang

Sheet DS- Title
A3: Lê Thanh Thản | B3: Chủ tịch Tập đoàn Mường Thanh
A4: Thái Thị Lan
A5: Lê Văn Bảy
A6: Lê Thanh Song
A7: Vũ Duy Kiên
A8: Trần Nam Trung
A9: Phạm Thanh Hải
A10: Trần Quang Khánh
A11: Tạ Vũ Toàn
A12: Nguyễn Đình Đề
A13: Nguyễn Thành Trung
A14: Nguyễn Đức Tuấn
A15: Phạm Ngọc Quý
... A26: Phạm Lịch Sự
A27: Lê Thị Hoàng Yến | B27: Tổng Giám Đốc Tập đoàn Mường Thanh
A28: Lê Thị Thu Hường
A29: Nguyễn Thị Minh
A30: Trần Thu Hiền
A31: Nguyễn Anh Ngọc
A32: Hoàng Thanh Trang
A33: Nguyễn Thj Thùy An
A34: Đặng Hồng Vân
A35: Võ Thị Phương Thảo
A36: Nguyễn Thu Trang
A37: Đặng Thu Huyền
A38: Võ Duy Tấn Huy
A39: Alice Nguyễn
... A43: Đỗ Anh Dũng
A44: Đỗ Trung Kiên | B44: Tổng Giám Đốc Cienco5
A45: Phạm Xuân Bình
A46: Lê Trọng Bằng
A47: Đỗ Anh Tuấn
A48: Trần Quốc Huy
A49: Nông Hồng Lộc
A50: Trần Tuấn Anh
A51: Nguyễn Thành Lợi
A52: Nguyễn Huy Thắng
A53: Đặng Trung Kiên
A54: Đoàn Khắc Thiện
A55: Tô Hữu Trường
...
